Workbook

Sheet Notes
A1: 46097 | B1: INcludes additional information regarding business recall date / annoucnement date (am using businesse recall date for now) | C1: CA
A2: 46097 | B2: Product Type would have to be fully captured again | C2: CA
A3: 46097 | B3: Adulterated: Prohibited Product | C3: CA
A4: 46097 | B4: The new style of categorized pesticides hides the practices from consumers, and which pesticides they may have been exposed to | C4: CA
A5: 46097 | B5: for connectedcannabis co _ why are there two different companies listed as the legal business name? which is correct? All point to same business website (https://recalls.cannabis.ca.gov/recalls/6761f90394a546fcd1a8843a, https://recalls.cannabis.ca.gov/recalls/6761c1de449a15805975db10) | C5: CA
A6: 46097 | B6: What is 'invalid batch testing' (see 'Canna America Live Resin Integrated Vaporizer')
A7: 46097 | B7: Lab isn't listed on recall notcied (note the amount of recalls around 2/205 like https://docs.google.com/spreadsheets/d/10YkN4Rqg58UGLMEH5R_pS1_9uNAoTdNG2UDLxc21FXs/edit?gid=665012503#gid=665012503 being recalled for incomplete testing due to no solvent testing
A8: 46097 | B8: Why different business names for Tonik Beverages? (go NXT LVL vs. baked betty's)
A9: 46097 | B9: So interesting that not one of the Oakfruitland (OFL) Pre-Roll had dates on the packaging! Wildf!
A10: 46097 | B10: Why was the Honey Edible recall given over a month betrween business recall and pub date? (https://recalls.cannabis.ca.gov/recalls/67f44320ef33cec4b8c75618)
A11: 46097 | B11: Weird no dates for ( smartweed flower)
A12: 46097 | B12: Adulterated: other is far too large, and isn't allowing CA good granularity Includes distributor without distributor license, no GMP, etc.
A13: 46098 | B13: Many of CO's Health Advisories do not contain information about the product
A14: 46098 | B14: https://drive.google.com/file/d/1_wFzm3GOJfzE6tmSqIhIcyvtI8ocZJDf/view - this case has batches that had Total Yeast and Mold but also identified other batches that were in teh same space as the contaminants
A15: 46098 | B15: Assuming 'elemental impurities' in the CO dataset indicate heavy metals
A16: 46098 | B16: CO Expansion: Includes a new pesticde :https://drive.google.com/file/d/155K5itnbbcG9r6nxemU_8UHDu709cMJB/view
A17: 46098 | B17: Why so amny actions in CO on 1/22
... A41: 46302 | B41: Is oregon just not doing recalls anymore, or have they stumbled into the safest product ever combined with their new lab?

Sheet State OV
A1: State | B1: Data | C1: Recall Page Link | D1: Recall Page Link | E1: Update Date | F1: notes
A2: Alabama | E2: 46296
A3: Alaska | B3: No | C3: https://www.commerce.alaska.gov/web/amco/ | E3: 46296 | F3: It's not only for recalls, so it doesn't count
A4: Arizona | B4: Yes | C4: https://www.azdhs.gov/preparedness/epidemiology-disease-control/food-safety-environmental-services/index.php#marijuana-kitchen-product-recalls | E4: 46296 | F4: Also need to check announcements
A5: Arkansas | B5: No | E5: 46296 | F5: No centralized place to record recalls, It's expected the dispensaries do so. No way to trace or understand supply chain safety issues. Boo.
A6: California | B6: Yes | C6: https://www.cannabis.ca.gov/consumers/cannabis-recalls-and-safety-notices/ | E6: 46296 | F6: Extensive Now
A7: Colorado | B7: Yes | C7: https://sbg.colorado.gov/med/health-and-safety-advisories | E7: 46297 | F7: press releases; not recalls, health advisories
A8: Connecticut | B8: No | C8: No Centralized Page found, but recalls evident | E8: 46297
A9: Delaware | B9: No | E9: 46297
A10: Florida | B10: No | E10: 46297
A11: Georgia | B11: No | E11: 46297
A12: Hawaii | B12: No | E12: 46297
A13: Idaho | E13: 46297
A14: Illinois | B14: No | C14: https://idfpr.illinois.gov/profs/cannabis.html | E14: 46297
A15: Indiana | E15: 46297
A16: Iowa | E16: 46297
A17: Kansas | E17: 46297
A18: Kentucky | B18: No | E18: 46297
A19: Louisiana | B19: No | E19: 46297
A20: Maine | B20: No | C20: https://www.maine.gov/dafs/ocp/resources/recalls | E20: 46297
A21: Maryland | B21: No | C21: https://cannabis.maryland.gov/pages/bulletins.aspx | E21: 46297
A22: Massachusetts | B22: No | C22: https://masscannabiscontrol.com/news/public-health-and-safety-advisories/ | E22: 46298
A23: Michigan | B23: Yes | C23: https://www.michigan.gov/cra/bulletins | E23: 46298
A24: Minnesota | B24: No | C24: https://mn.gov/ocm/businesses/recalls.jsp | E24: 46298 | F24: ...only hemp recalls? Really?
A25: Mississippi | B25: No | C25: https://www.mmcp.ms.gov/patient-purchased-recall-items | E25: 46298
A26: Missouri | B26: No | C26: https://health.mo.gov/business-professionals/cannabis-regulation/licensee-compliance-and-guidance/product-recalls | E26: 46299
A27: Montana | B27: Yes | C27: https://revenue.mt.gov/card/cannabis/cannabis-product-recalls | E27: 46300 | F27: but have no recalls yet
A28: Nebraska | E28: 46301
A29: Nevada | B29: Yes | C29: https://ccb.nv.gov/guidance/#item-1 | E29: 46302
A30: New Hampshire | B30: No | E30: 46302
A31: New Jersey | B31: Yes | C31: https://www.nj.gov/cannabis/adult-personal/recalls/ | E31: 46303 | F31: None listed; some in press
A32: New Mexico | B32: Yes | C32: https://www.rld.nm.gov/cannabis/data-news/cannabis-recalls/ | E32: 46304
A33: New York | B33: No | C33: https://cannabis.ny.gov/recalls | D33: New | E33: 46305 | F33: It says they will be posted on that page but the unregulated hemp products they recalled aren't included.
A34: North Dakota | B34: No | E34: 46306
A35: Ohio | B35: Yes | C35: https://com.ohio.gov/divisions-and-programs/cannabis-control/product-safety | E35: 46306 | F35: One from December not included
A36: Oklahoma | B36: Yes | C36: https://oklahoma.gov/omma/recalls/embargoed-and-recalled-products.html | E36: 46306
A37: Oregon | B37: Yes | C37: https://www.oregon.gov/olcc/Pages/product-recalls.aspx | E37: 46306
A38: Pennsylvania | B38: No | E38: 46306
A39: Rhode Island | B39: No | E39: 46306
A40: South Carolina | E40: 46306
...

Sheet Recall Analysis
A1: ID | B1: Business Recall Date | C1: Reg Recall Ann | D1: State | E1: Link | F1: Web Archive Link | G1: Type | H1: Product Type | I1: Brand Name / Product Name | J1: Company / Producer | K1: Lab | L1: MSO | M1: Dated? | N1: Harvest or Package Date | O1: Sale Date | P1: Reason | Q1: Source | R1: Category | S1: Tight Category
A2: 43781AlaskaCalm N Collective, LLC | C2: 43781 | D2: Alaska | E2: https://web.archive.org/web/20230619022017/https://www.commerce.alaska.gov/web/Portals/9/pub/MCB/Minutes/2020/01.23/Tab6.pdf#page=7#page=7 | F2: https://web.archive.org/web/20230619022017/https://www.commerce.alaska.gov/web/Portals/9/pub/MCB/Minutes/2020/01.23/Tab6.pdf#page=7#page=7 | G2: Mandatory | H2: Unspecified | I2: Calm N Collective | J2: Calm N Collective, LLC | M2: N | P2: Clonex, Root Pac, Big Time Exterminator, Super Thrive | Q2: State Page | R2: =VLOOKUP(P2,Categorizations!A:C,2,FALSE()) -> Pesticides | S2: =VLOOKUP(P2,Categorizations!A:C,3,FALSE()) -> Pesticides
A3: 44988AlaskaWill’s World Extracts | C3: 44988 | D3: Alaska | E3: https://web.archive.org/web/20250719042132/https://www.commerce.alaska.gov/web/Portals/9/pub/HomePage/Press%20Release/Director%20Advisory.administrativehold.3.2.23.final%20(2).pdf | F3: https://web.archive.org/web/20250719042132/https://www.commerce.alaska.gov/web/Portals/9/pub/HomePage/Press%20Release/Director%20Advisory.administrativehold.3.2.23.final%20(2).pdf | G3: Mandatory | H3: Concentrates | I3: All marijuana concentrates in any form and infused joints manufactured by Will’s World Extracts, | J3: Will’s World Extracts | M3: N | P3: unregistered and unlicensed THC concentrates | Q3: State Recall Page | R3: =VLOOKUP(P3,Categorizations!A:C,2,FALSE()) -> Diverted Product | S3: =VLOOKUP(P3,Categorizations!A:C,3,FALSE()) -> Prohibited Additives / Product
A4: =CONCATENATE(C4,J4) -> 44370Harvest Platinum | C4: 44370 | D4: Arizona | E4: https://web.archive.org/web/20260000000000*/https://www.azdhs.gov/director/public-information-office/index.php#news-release-062321 | F4: https://web.archive.org/web/20260000000000*/https://www.azdhs.gov/director/public-information-office/index.php#news-release-062321 | G4: Voluntary | H4: Flower | I4: Harvest Platinum 14g Pre Pack Indica Flower (Glazed Apricot Gelato) | J4: Harvest Platinum | M4: C | N4: 44292 | P4: Salmonella | Q4: State Recall Page | R4: =VLOOKUP(P4,Categorizations!A:C,2,FALSE()) -> Salmonella | S4: =VLOOKUP(P4,Categorizations!A:C,3,FALSE()) -> Microbial Contamination
A5: 44370Harvest Platinum 2 | C5: 44370 | D5: Arizona | E5: https://www.azdhs.gov/director/public-information-office/index.php#news-release-062321 | G5: Voluntary | H5: Flower | I5: Harvest Platinum 14g Pre Pack Sativa Flower (Tiger Haze) | J5: Harvest Platinum | M5: C | N5: 44292 | P5: Aspergillus | Q5: State Recall Page | R5: =VLOOKUP(P5,Categorizations!A:C,2,FALSE()) -> Aspergillus | S5: =VLOOKUP(P5,Categorizations!A:C,3,FALSE()) -> Microbial Contamination
A6: =CONCATENATE(C6,J6) -> 44370Modern Flower | C6: 44370 | D6: Arizona | E6: https://www.azdhs.gov/director/public-information-office/index.php#news-release-062321 | G6: Voluntary | H6: Flower | I6: Modern Flower 3.5g Pre Pack Indica Flower (Orange Acai) | J6: Modern Flower | M6: C | N6: 44307 | P6: Aspergillus sp. | Q6: State Recall Page | R6: =VLOOKUP(P6,Categorizations!A:C,2,FALSE()) -> Aspergillus | S6: =VLOOKUP(P6,Categorizations!A:C,3,FALSE()) -> Microbial Contamination
A7: =CONCATENATE(C7,J7) -> 44370Sol Flower | C7: 44370 | D7: Arizona | E7: https://www.azdhs.gov/director/public-information-office/index.php#news-release-062321 | G7: Voluntary | H7: Flower | I7: Sol Flower Dispensaries and Establishments Tahiti Lime | J7: Sol Flower | M7: C | N7: 44217 | P7: Aspergillus sp. | Q7: State Recall Page | R7: =VLOOKUP(P7,Categorizations!A:C,2,FALSE()) -> Aspergillus | S7: =VLOOKUP(P7,Categorizations!A:C,3,FALSE()) -> Microbial Contamination
A8: =CONCATENATE(C8,J8) -> 44370EHF | C8: 44370 | D8: Arizona | E8: https://www.azdhs.gov/director/public-information-office/index.php#news-release-062321 | G8: Voluntary | H8: Flower | I8: EHF (Elephant Head Farms) HAT Trick #17 Flower | J8: EHF | M8: C | N8: 44263 | P8: Salmonella | Q8: State Recall Page | R8: =VLOOKUP(P8,Categorizations!A:C,2,FALSE()) -> Salmonella | S8: =VLOOKUP(P8,Categorizations!A:C,3,FALSE()) -> Microbial Contamination
A9: =CONCATENATE(C9,J9) -> 44370Mohave | C9: 44370 | D9: Arizona | E9: https://www.azdhs.gov/director/public-information-office/index.php#news-release-062321 | G9: Voluntary | H9: Pre-Roll | I9: Mohave Cannabis Preroll | J9: Mohave | M9: N | P9: Salmonella | Q9: State Recall Page | R9: =VLOOKUP(P9,Categorizations!A:C,2,FALSE()) -> Salmonella | S9: =VLOOKUP(P9,Categorizations!A:C,3,FALSE()) -> Microbial Contamination
A10: =CONCATENATE(C10,J10) -> 44370Tru Infusion | C10: 44370 | D10: Arizona | E10: https://www.azdhs.gov/director/public-information-office/index.php#news-release-062321 | G10: Voluntary | H10: Flower | I10: Tru Infusion Flower Caked Up Cherries | J10: Tru Infusion | M10: C | N10: 44281 | P10: Aspergillus sp. | Q10: State Recall Page | R10: =VLOOKUP(P10,Categorizations!A:C,2,FALSE()) -> Aspergillus | S10: =VLOOKUP(P10,Categorizations!A:C,3,FALSE()) -> Microbial Contamination
A11: =CONCATENATE(C11,J11) -> 44370Pharm Chemistry | C11: 44370 | D11: Arizona | E11: https://www.azdhs.gov/director/public-information-office/index.php#news-release-062321 | G11: Voluntary | H11: Flower, Pre-Roll | I11: The Pharm Chemistry #1 (HD 3/24/21) | J11: Pharm Chemistry | M11: N | P11: Aspergillus sp. | Q11: State Recall Page | R11: =VLOOKUP(P11,Categorizations!A:C,2,FALSE()) -> Aspergillus | S11: =VLOOKUP(P11,Categorizations!A:C,3,FALSE()) -> Microbial Contamination
A12: 44511ArizonaBaked Bros / Toasted | C12: 44511 | D12: Arizona | E12: https://www.azdhs.gov/director/public-information-office/index.php#news-release-111121 | G12: Voluntary | H12: Flower | I12: Baked Bros | J12: Baked Bros | M12: N | P12: Salmonella | Q12: State Recall Page | R12: =VLOOKUP(P12,Categorizations!A:C,2,FALSE()) -> Salmonella | S12: =VLOOKUP(P12,Categorizations!A:C,3,FALSE()) -> Microbial Contamination
A13: 44511ArizonaToasted | C13: 44511 | D13: Arizona | E13: https://www.azdhs.gov/director/public-information-office/index.php#news-release-111121 | G13: Voluntary | H13: Distillate | I13: Toasted | J13: Toasted | M13: N | P13: Aspergillus sp. | Q13: State Recall Page | R13: =VLOOKUP(P13,Categorizations!A:C,2,FALSE()) -> Aspergillus | S13: =VLOOKUP(P13,Categorizations!A:C,3,FALSE()) -> Microbial Contamination
A14: 44875ArizonaPP Wellness | C14: 44875 | D14: Arizona | E14: https://www.azdhs.gov/director/public-information-office/index.php#news-release-111022 | G14: Voluntary | H14: Flower | I14: PP Wellness El Alquimista | J14: PP Wellness | M14: N | P14: Aspergillus sp. | Q14: State Recall Page | R14: =VLOOKUP(P14,Categorizations!A:C,2,FALSE()) -> Aspergillus | S14: =VLOOKUP(P14,Categorizations!A:C,3,FALSE()) -> Microbial Contamination
A15: 44875ArizonaPP Wellness2 | C15: 44875 | D15: Arizona | E15: https://www.azdhs.gov/director/public-information-office/index.php#news-release-111022 | G15: Voluntary | H15: Flower | I15: PP Wellness Tangie Head | J15: PP Wellness | M15: N | P15: Aspergillus sp. | Q15: State Recall Page | R15: =VLOOKUP(P15,Categorizations!A:C,2,FALSE()) -> Aspergillus | S15: =VLOOKUP(P15,Categorizations!A:C,3,FALSE()) -> Microbial Contamination
A16: 44875ArizonaPP Wellness3 | C16: 44875 | D16: Arizona | E16: https://www.azdhs.gov/director/public-information-office/index.php#news-release-111022 | G16: Voluntary | H16: Flower | I16: PP Wellness Nasty Girl | J16: PP Wellness | M16: N | P16: Aspergillus sp. | Q16: State Recall Page | R16: =VLOOKUP(P16,Categorizations!A:C,2,FALSE()) -> Aspergillus | S16: =VLOOKUP(P16,Categorizations!A:C,3,FALSE()) -> Microbial Contamination
A17: 44875ArizonaPP Wellness4 | C17: 44875 | D17: Arizona | E17: https://www.azdhs.gov/director/public-information-office/index.php#news-release-111022 | G17: Voluntary | H17: Flower | I17: PP Wellness The Juice | J17: PP Wellness | M17: N | P17: Aspergillus sp. | Q17: State Recall Page | R17: =VLOOKUP(P17,Categorizations!A:C,2,FALSE()) -> Aspergillus | S17: =VLOOKUP(P17,Categorizations!A:C,3,FALSE()) -> Microbial Contamination
A18: 44875ArizonaPP Wellness5 | C18: 44875 | D18: Arizona | E18: https://www.azdhs.gov/director/public-information-office/index.php#news-release-111022 | G18: Voluntary | H18: Flower | I18: PP Wellness Gorilla Grapevine | J18: PP Wellness | M18: N | P18: Aspergillus sp. | Q18: State Recall Page | R18: =VLOOKUP(P18,Categorizations!A:C,2,FALSE()) -> Aspergillus | S18: =VLOOKUP(P18,Categorizations!A:C,3,FALSE()) -> Microbial Contamination
A19: 44875ArizonaPP Wellness6 | C19: 44875 | D19: Arizona | E19: AZDHS | Financial Services | G19: Voluntary | H19: Flower | I19: PP Wellness The Juice | J19: PP Wellness | M19: N | P19: Aspergillus sp. | Q19: State Recall Page | R19: =VLOOKUP(P19,Categorizations!A:C,2,FALSE()) -> Aspergillus | S19: =VLOOKUP(P19,Categorizations!A:C,3,FALSE()) -> Microbial Contamination
A20: =CONCATENATE(C20,D20,J20) -> 45006ArizonaSource One Meds | C20: 45006 | D20: Arizona | E20: https://www.azdhs.gov/policy-intergovernmental-affairs/index.php#news-release-032123 | G20: Voluntary | H20: Flower | I20: Muddy Waters | J20: Source One Meds | M20: N | P20: Aspergillus | Q20: State Recall Page | R20: =VLOOKUP(P20,Categorizations!A:C,2,FALSE()) -> Aspergillus | S20: =VLOOKUP(P20,Categorizations!A:C,3,FALSE()) -> Microbial Contamination
A21: =CONCATENATE(C21,D21,J21) -> 45006ArizonaNature’s Wonder | C21: 45006 | D21: Arizona | E21: https://www.azdhs.gov/director/public-information-office/index.php#news-release-032123 | G21: Voluntary | H21: Flower | I21: Mango Sunrise | J21: Nature’s Wonder | M21: N | P21: Aspergillus | Q21: State Recall Page | R21: =VLOOKUP(P21,Categorizations!A:C,2,FALSE()) -> Aspergillus | S21: =VLOOKUP(P21,Categorizations!A:C,3,FALSE()) -> Microbial Contamination
A22: =CONCATENATE(C22,D22,J22) -> 45006ArizonaPotent Planet | C22: 45006 | D22: Arizona | E22: https://www.azdhs.gov/director/public-information-office/index.php#news-release-032123 | G22: Voluntary | H22: Flower | I22: Blood Oath | J22: Potent Planet | M22: N | P22: Aspergillus | Q22: State Recall Page | R22: =VLOOKUP(P22,Categorizations!A:C,2,FALSE()) -> Aspergillus | S22: =VLOOKUP(P22,Categorizations!A:C,3,FALSE()) -> Microbial Contamination
A23: =CONCATENATE(C23,D23,J23) -> 45006ArizonaDeep Root pHarm | C23: 45006 | D23: Arizona | E23: https://www.azdhs.gov/director/public-information-office/index.php#news-release-032123 | G23: Voluntary | H23: Flower | I23: Jenny Kush | J23: Deep Root pHarm | M23: N | P23: Aspergillus | Q23: State Recall Page | R23: =VLOOKUP(P23,Categorizations!A:C,2,FALSE()) -> Aspergillus | S23: =VLOOKUP(P23,Categorizations!A:C,3,FALSE()) -> Microbial Contamination
A24: =CONCATENATE(C24,D24,J24,2) -> 45006ArizonaDeep Root pHarm2 | C24: 45006 | D24: Arizona | E24: https://www.azdhs.gov/director/public-information-office/index.php#news-release-032123 | G24: Voluntary | H24: Flower | I24: Big Mac | J24: Deep Root pHarm | M24: N | P24: Aspergillus | Q24: State Recall Page | R24: =VLOOKUP(P24,Categorizations!A:C,2,FALSE()) -> Aspergillus | S24: =VLOOKUP(P24,Categorizations!A:C,3,FALSE()) -> Microbial Contamination
A25: 45079ArizonaTruinfusion | C25: 45079 | D25: Arizona | E25: https://www.azdhs.gov/policy-intergovernmental-affairs/index.php#news-release-060223 | G25: Voluntary | H25: Flower | I25: Truinfusion Zombie Cookies | J25: Truinfusion | M25: N | P25: Aspergillus | Q25: State Page | R25: =VLOOKUP(P25,Categorizations!A:C,2,FALSE()) -> Aspergillus | S25: =VLOOKUP(P25,Categorizations!A:C,3,FALSE()) -> Microbial Contamination
A26: 45079ArizonaTruinfusion2 | C26: 45079 | D26: Arizona | E26: https://www.azdhs.gov/policy-intergovernmental-affairs/index.php#news-release-060223 | G26: Voluntary | H26: Flower | I26: Truinfusion Peach Gas | J26: Truinfusion | M26: N | P26: Aspergillus | Q26: State Page | R26: =VLOOKUP(P26,Categorizations!A:C,2,FALSE()) -> Aspergillus | S26: =VLOOKUP(P26,Categorizations!A:C,3,FALSE()) -> Microbial Contamination
A27: =CONCATENATE(C27,D27,J27) -> 45131ArizonaGrow Sciences | C27: 45131 | D27: Arizona | E27: https://www.azdhs.gov/policy-intergovernmental-affairs/index.php#news-release-072423 | G27: Voluntary | H27: Flower | I27: Grow Sciences Divinity | J27: Grow Sciences | L27: Y | M27: N | P27: Aspergillus | Q27: State Page | R27: =VLOOKUP(P27,Categorizations!A:C,2,FALSE()) -> Aspergillus | S27: =VLOOKUP(P27,Categorizations!A:C,3,FALSE()) -> Microbial Contamination
A28: =CONCATENATE(C28,D28,J28) -> 45131ArizonaGrow Sciences | C28: 45131 | D28: Arizona | E28: https://www.azdhs.gov/policy-intergovernmental-affairs/index.php#news-release-072423 | G28: Voluntary | H28: Flower | I28: Grow Sciences MAC | J28: Grow Sciences | L28: Y | M28: N | P28: Aspergillus | Q28: State Page | R28: =VLOOKUP(P28,Categorizations!A:C,2,FALSE()) -> Aspergillus | S28: =VLOOKUP(P28,Categorizations!A:C,3,FALSE()) -> Microbial Contamination
A29: =CONCATENATE(C29,D29,J29) -> 45131ArizonaGrow Sciences | C29: 45131 | D29: Arizona | E29: https://www.azdhs.gov/policy-intergovernmental-affairs/index.php#news-release-072423 | G29: Voluntary | H29: Flower | I29: Grow Sciences MAC | J29: Grow Sciences | L29: Y | M29: N | P29: Aspergillus | Q29: State Page | R29: =VLOOKUP(P29,Categorizations!A:C,2,FALSE()) -> Aspergillus | S29: =VLOOKUP(P29,Categorizations!A:C,3,FALSE()) -> Microbial Contamination
A30: =CONCATENATE(C30,D30,J30) -> 45131ArizonaSoothing Options | C30: 45131 | D30: Arizona | E30: https://www.azdhs.gov/policy-intergovernmental-affairs/index.php#news-release-072423 | G30: Voluntary | H30: Flower | I30: Soothing Options Gelato 41 | J30: Soothing Options | M30: N | P30: Aspergillus | Q30: State Page | R30: =VLOOKUP(P30,Categorizations!A:C,2,FALSE()) -> Aspergillus | S30: =VLOOKUP(P30,Categorizations!A:C,3,FALSE()) -> Microbial Contamination
A31: =CONCATENATE(C31,D31,J31) -> 45145ArizonaNirvana Center | C31: 45145 | D31: Arizona | E31: https://www.azdhs.gov/policy-intergovernmental-affairs/index.php#news-release-080723 | G31: Voluntary | H31: Flower | I31: Nirvana Center Cloud 9 Gummies (Grape) | J31: Nirvana Center | M31: N | P31: Salmonella | Q31: State Page | R31: =VLOOKUP(P31,Categorizations!A:C,2,FALSE()) -> Salmonella | S31: =VLOOKUP(P31,Categorizations!A:C,3,FALSE()) -> Microbial Contamination
A32: =CONCATENATE(C32,D32,J32) -> 45162ArizonaGrow Sciences | C32: 45162 | D32: Arizona | E32: https://www.azdhs.gov/policy-intergovernmental-affairs/index.php#news-release-082323 | G32: Voluntary | H32: Flower | I32: Grow Sciences Tropicana Punch | J32: Grow Sciences | L32: Y | M32: N | P32: Aspergillus | Q32: State Page | R32: =VLOOKUP(P32,Categorizations!A:C,2,FALSE()) -> Aspergillus | S32: =VLOOKUP(P32,Categorizations!A:C,3,FALSE()) -> Microbial Contamination
A33: =CONCATENATE(C33,D33,J33) -> 45219ArizonaCuraleaf | C33: 45219 | D33: Arizona | E33: https://www.azdhs.gov/policy-intergovernmental-affairs/index.php#news-release-102023 | G33: Voluntary | H33: Flower | I33: Curaleaf MnC | J33: Curaleaf | L33: Y | M33: N | P33: Aspergillus | Q33: State Page | R33: =VLOOKUP(P33,Categorizations!A:C,2,FALSE()) -> Aspergillus | S33: =VLOOKUP(P33,Categorizations!A:C,3,FALSE()) -> Microbial Contamination
A34: =CONCATENATE(C34,D34,J34) -> 45239ArizonaGLOBE FARMACY INC. | C34: 45239 | D34: Arizona | E34: https://www.azdhs.gov/policy-intergovernmental-affairs/index.php#news-release-110923 | G34: Voluntary | H34: Concentrate | I34: GLOBE FARMACY INC. EX LR GUAVA MAC | J34: GLOBE FARMACY INC. | M34: N | P34: Aspergillus | Q34: State Page | R34: =VLOOKUP(P34,Categorizations!A:C,2,FALSE()) -> Aspergillus | S34: =VLOOKUP(P34,Categorizations!A:C,3,FALSE()) -> Microbial Contamination
A35: =CONCATENATE(C35,D35,J35,2) -> 45239ArizonaGLOBE FARMACY INC.2 | C35: 45239 | D35: Arizona | E35: https://www.azdhs.gov/policy-intergovernmental-affairs/index.php#news-release-110923 | G35: Voluntary | H35: Concentrate | I35: GLOBE FARMACY INC. EX LHR ORZ | J35: GLOBE FARMACY INC. | M35: N | P35: Aspergillus | Q35: State Page | R35: =VLOOKUP(P35,Categorizations!A:C,2,FALSE()) -> Aspergillus | S35: =VLOOKUP(P35,Categorizations!A:C,3,FALSE()) -> Microbial Contamination
A36: =CONCATENATE(C36,D36,J36) -> 45257ArizonaNirvana Center | C36: 45257 | D36: Arizona | E36: https://www.azdhs.gov/policy-intergovernmental-affairs/index.php#news-release-112723 | G36: Voluntary | H36: Flower | I36: Nirvana Center Grim Reefer | J36: Nirvana Center | M36: N | P36: Aspergillus | Q36: State Page | R36: =VLOOKUP(P36,Categorizations!A:C,2,FALSE()) -> Aspergillus | S36: =VLOOKUP(P36,Categorizations!A:C,3,FALSE()) -> Microbial Contamination
A37: =CONCATENATE(C37,D37,J37) -> 45418ArizonaThe Flower Shop | C37: 45418 | D37: Arizona | E37: https://www.azdhs.gov/policy-intergovernmental-affairs/index.php#news-release-050624 | G37: Voluntary | H37: Flower | I37: The Flower Shop | J37: The Flower Shop | M37: N | P37: Aspergillus | Q37: State Page | R37: =VLOOKUP(P37,Categorizations!A:C,2,FALSE()) -> Aspergillus | S37: =VLOOKUP(P37,Categorizations!A:C,3,FALSE()) -> Microbial Contamination
A38: =CONCATENATE(C38,D38,J38) -> 45483ArizonaNature’s Wonder Inc | C38: 45483 | D38: Arizona | E38: https://www.azdhs.gov/documents/policy-intergovernmental-affairs/public-information/news-releases/news-release-for-recall-7-10-24.pdf | G38: Voluntary | H38: Concentrate | I38: DIME Mint OG | J38: Nature’s Wonder Inc | M38: N | P38: Piperonyl butoxide (Pesticide) | Q38: State Page | R38: =VLOOKUP(P38,Categorizations!A:C,2,FALSE()) -> Pesticides | S38: =VLOOKUP(P38,Categorizations!A:C,3,FALSE()) -> Pesticides
A39: =CONCATENATE(C39,J39) -> 45955Elba Holdings | C39: 45955 | D39: Arizona | E39: https://arizonastatecannabis.org/news-25oct2025 | G39: Voluntary | H39: Flower | I39: Elba Holdings | J39: Elba Holdings | P39: Aspergillus, Lead | Q39: Press | R39: =VLOOKUP(P39,Categorizations!A:C,2,FALSE()) -> Aspergillus | S39: =VLOOKUP(P39,Categorizations!A:C,3,FALSE()) -> Multiple
A40: =CONCATENATE(C40,J40) -> 46009Pressd / Baked Bros | C40: 46009 | D40: Arizona | E40: https://www.fox10phoenix.com/news/arizona-announces-marijuana-recall-amid-contamination-worries-heres-what-know | G40: Voluntary | H40: Concentrate, Edibles | I40: Pressd / Baked Bros | J40: Pressd / Baked Bros | K40: Kaycha | P40: Spinosad | Q40: Press | R40: =VLOOKUP(P40,Categorizations!A:C,2,FALSE()) -> Pesticides | S40: =VLOOKUP(P40,Categorizations!A:C,3,FALSE()) -> Pesticides
...

Sheet Categorizations
A1: Reason | B1: Category | C1: Tight Cat
A2: Bifenthrin and Chlorfenapyr | B2: Pesticides | C2: Pesticides
A3: Pyrethrins and Piperonyl butoxide | B3: Pesticides | C3: Pesticides
A4: Abamectin | B4: Pesticides | C4: Pesticides
A5: imidacloprid and myclobutanil | B5: Pesticides | C5: Pesticides
A6: permethrin, spiromesifen | B6: Pesticides | C6: Pesticides
A7: malathion | B7: Pesticides | C7: Pesticides
A8: Ethephon | B8: Pesticides | C8: Pesticides
A9: unspecified pesticide | B9: Pesticides | C9: Pesticides
A10: Diuron | B10: Pesticides | C10: Pesticides
A11: Bifenthrin and Diuron | B11: Pesticides | C11: Pesticides
A12: Pyriproxyfen | B12: Pesticides | C12: Pesticides
... A314: Methylene Chloride | B314: Solvent | C314: Solvent

Sheet Rescinded
B1: 46251 | C1: 46252 | D1: California | F1: https://web.archive.org/web/20260904163707/https://recalls.cannabis.ca.gov/recalls/6a7df35de9866a4e68ffcaec | G1: Voluntary | H1: Beverage | I1: St Ides Beverage | J1: LP Roadrunner Logistics LLC | M1: Y | P1: incomplete and incorrect regulatory compliance testing. | Q1: State Recall Page | R1: =VLOOKUP(P1,Categorizations!A:C,2,FALSE()) -> Incomplete Testing | S1: =VLOOKUP(P1,Categorizations!A:C,3,FALSE()) -> Lab Issue | T1: Pabst Labs

Sheet Categorization Explode Multiple
A1: Reason | B1: Category | C1: Tight Cat
A2: Bifenthrin and Chlorfenapyr | B2: Pesticides | C2: Pesticides
A3: Pyrethrins and Piperonyl butoxide | B3: Pesticides | C3: Pesticides
A4: Abamectin | B4: Pesticides | C4: Pesticides
A5: imidacloprid and myclobutanil | B5: Pesticides | C5: Pesticides
A6: permethrin, spiromesifen | B6: Pesticides | C6: Pesticides
A7: malathion | B7: Pesticides | C7: Pesticides
A8: Ethephon | B8: Pesticides | C8: Pesticides
A9: unspecified pesticide | B9: Pesticides | C9: Pesticides
A10: Diuron | B10: Pesticides | C10: Pesticides
A11: Bifenthrin and Diuron | B11: Pesticides | C11: Pesticides
A12: Pyriproxyfen | B12: Pesticides | C12: Pesticides
... A331: Spinosad | B331: Pesticides | C331: Pesticides

Sheet Allowable Pesticide List Links
A1: State | B1: Data
A2: Alabama
A3: Alaska | B3: No | C3: https://dec.alaska.gov/media/xnzhit1j/cannabis-pesticides.pdf
A4: Arizona | B4: Yes
A5: Arkansas | B5: No
A6: California | B6: Yes
A7: Colorado | B7: Yes | C7: https://docs.google.com/spreadsheets/d/14MpUpc-DCLQgKCfcz2uNeroNCO4ILNHA6lwM0CawudU/edit?gid=366976881#gid=366976881
A8: Connecticut | B8: No
A9: Delaware | B9: No
A10: Florida | B10: No
A11: Georgia | B11: No
A12: Hawaii | B12: No
A13: Idaho
A14: Illinois | B14: No
A15: Indiana
A16: Iowa
A17: Kansas
A18: Kentucky | B18: No
A19: Louisiana | B19: No
A20: Maine | B20: No
A21: Maryland | B21: No
A22: Massachusetts | B22: No
A23: Michigan | B23: Yes
A24: Minnesota | B24: No
A25: Mississippi | B25: No
A26: Missouri | B26: No
A27: Montana | B27: Yes
A28: Nebraska
A29: Nevada | B29: Yes
A30: New Hampshire | B30: No
A31: New Jersey | B31: Yes
A32: New Mexico | B32: Yes
A33: New York | B33: No
A34: North Dakota | B34: No
A35: Ohio | B35: Yes
A36: Oklahoma | B36: Yes
A37: Oregon | B37: Yes
A38: Pennsylvania | B38: No
A39: Rhode Island | B39: No
A40: South Carolina
...

Sheet Pesticides
A1: Reason | B1: Pesticides
A2: Pyrethrins and Piperonyl butoxide | B2: Pyrethrins
A3: Pyrethrins and Piperonyl butoxide | B3: Piperonyl butoxide
A4: Abamectin | B4: Abamectin
A5: Bifenthrin and Chlorfenapyr | B5: Bifenthrin
A6: Bifenthrin and Chlorfenapyr | B6: Chlorfenapyr
A7: myclobutanil and etoxazole | B7: Myclobutanil
A8: myclobutanil and etoxazole | B8: Etoxazole
A9: imidacloprid and myclobutanil | B9: Myclobutanil
A10: imidacloprid and myclobutanil | B10: Imidacloprid
A11: permethrin, spiromesifen | B11: spiromesifen
A12: permethrin, spiromesifen | B12: permethrin
... A130: Spinosad | B130: Spinosad

Sheet Pesticide Info
A1: Pesticide Name | B1: Colorado | C1: California | D1: Group1 | E1: Group2 | F1: Group3
A2: Abamectin | D2: insecticide | E2: acaricide | F2: nematicide
A3: Avermectin | D3: insecticide
A4: Azoxystrobin | D4: broad spectrum systemic fungicide
A5: Bifenazate | D5: miticide | E5: systemic and non-systemic miticides | F5: acaricide
A6: Bifenthrin | D6: insecticide | E6: pyrethoid insecticide
A7: Chlorfenapyr | D7: insecticide
A8: Cypermethrin
A9: Daminozide
A10: Dichlenobil
A11: Diphenylamine (DPA)
A12: Diuron
A13: Ethephon
A14: Etoxazole
A15: Fluopyram
A16: Fluopyram.
A17: hexythiazox
A18: Imidacloprid
A19: indolbutyric acid (IBA) | B19: Onlist | C19: Onlist
A20: malathion
A21: Malathion A
A22: Myclobutanil
A23: O-phenylphenol
A24: O-phenylphenol (OPP)
A25: paclobutrazal
A26: paclobutrazol
A27: permethrin
A28: Piperonyl butoxide | B28: Onlist | C28: Onlist
A29: Propiconazole
A30: Pyrethrins | B30: Onlist | C30: Onlist
A31: Pyridaben
A32: Pyrimethanil
A33: Pyriproxyfen
A34: Spinosad
A35: Spinosad
A36: Spinosyn
A37: Spinosyn A
A38: Spiromefesin
A39: spiromesifen
A40: Spiromesifin
...

Sheet California Allowables
A1: Can Be Used on Cannabis? Y or N | B1: Restrictions & Exceptions | C1: Registrant | D1: EPA Registration Number | E1: Active Ingredient(s) | F1: Pesticide Type | G1: DPR Stamped Date* For Internal Use Only
A2: Y | B2: This product is restricted to use in nurseries. | C2: OHP, Inc. | D2: 70051-19-AA-59807 | E2: Isaria fumosorosea apopka strain 97 (ATCC 20874) | F2: Insecticide | G2: 42653
A3: Y | B3: N/A | C3: Becker Microbial Products, Inc. | D3: 62637-3-ZA | E3: Bacilllus thuringiensis subspecies israelensis strain BMP 144 | F3: Insecticide | G3: 41456
A4: Y | B4: For mosquito control as directed on the label | C4: Becker Microbial Products, Inc. | D4: 62637-1-ZA | E4: Bacilllus thuringiensis subspecies israelensis strain BMP 144 | F4: Insecticide | G4: 4/40/22
A5: Y | B5: This product is an adjuvant. It can be used with other registered products that meet the legal criteria for use on cannabis, but not independently. | C5: Aquatrols Corporation of America | D5: 9037-50003-AA | E5: N/A | F5: Adjuvant | G5: 43720
A6: Y | B6: This product is an adjuvant. It can be used with other registered products that meet the legal criteria for use on cannabis, but not independently. | C6: Aquatrols Corporation of America | D6: 9037-50003-AA | E6: N/A | F6: Adjuvant | G6: 39486
A7: Y | B7: N/A | C7: Athena Ag, Inc. | D7: 82752-1-AA-93752 | E7: IBA (indole-3-butyric acid) | F7: Plant Growth Regulator | G7: 43816
A8: Y | B8: N/A | C8: Atticus, LLC | D8: 91234-306-AA | E8: Azadirachtin | F8: Insecticide | G8: 45658
A9: Y | B9: N/A | C9: Atticus, LLC | D9: 91234-305-AA | E9: Azadirachtin | F9: Miticide, Insecticide, Nematacide | G9: 45965
A10: Y | B10: This product is restricted to indoor use, including greenhouses. | C10: Biosafe Systems, LLC | D10: 70299-23-AA | E10: Ammonium nonanoate | F10: Herbicide | G10: 41754
A11: Y | B11: N/A | C11: Gowan Company, LLC | D11: 71908-1-AA-10163 | E11: Azadirachtin | F11: Insecticide, Insect Repellent | G11: 40521
A12: Y | B12: N/A | C12: Biosafe Systems, LLC | D12: 70299-17-AA | E12: Azadirachtin | F12: Insecticide, Nematicide | G12: 43133
A13: Y | B13: N/A | C13: Parry America Inc. | D13: 71908-1-AA-81268 | E13: Azadirachtin | F13: Insecticide, Miticide, Nematicide | G13: 43476
A14: Y | B14: N/A | C14: Arborjet, Inc. | D14: 81899-4-AA-74578 | E14: Azadirachtin | F14: Insecticide, Nematicide | G14: 43613
A15: Y | B15: N/A | C15: Arborjet, Inc. | D15: 81899-4-ZA-74578 | E15: Azadirachtin | F15: Insecticide | G15: 44320
A16: Y | B16: N/A | C16: OHP, Inc. | D16: 70051-9-AA-59807 | E16: Azadirachtin | F16: Insecticide | G16: 44743
... A23: Y | B23: N/A | C23: Bonide Products, LLC | D23: 67702-54-ZB-4 | E23: Caprylic acid, capric acid | F23: Herbicide, Algaecide | G23: 43182
A24: Y | C24: Certis USA, LLC | D24: 82074-5-ZA | E24: Pyrethrins, Beauveria bassiana strain: GHA | F24: Insecticide | G24: 44257
A25: Y | B25: N/A | C25: Lawn And Garden Products, Inc. | D25: 1021-1771-AA-54705 | E25: Pyrethrins | F25: Insecticide | G25: 44362
A26: Y | B26: N/A | C26: Bonide Products, LLC | D26: 67702-54-ZA-4 | E26: Caprylic acid, capric acid | F26: Herbicide, Algaecide | G26: 43958
A27: Y | B27: N/A | C27: Bonide Products, LLC | D27: 67702-59-ZA-4 | E27: Caprylic acid, capric acid | F27: Herbicide, Algaecide | G27: 43843
A28: Y | B28: N/A | C28: Bonide Products, LLC | D28: 67702-54-AA-4 | E28: Caprylic acid, capric acid | F28: Herbicide, Algaecide | G28: 44092
A29: Y | B29: N/A | C29: Bonide Products, LLC | D29: 67702-59-AA-4 | E29: Caprylic acid, capric acid | F29: Herbicide, Algaecide | G29: 42464
A30: Y | B30: N/A | C30: Gowan Company, LLC | D30: 10163-326-AA | E30: Capsicum oleoresin, soybean oil, garlic | F30: Insecticide, Repellent | G30: 44258
A31: Y | B31: N/A | C31: Gowan Company, LLC | D31: 10163-336-AA | E31: Capsicum oleoresin, soybean oil, garlic | F31: Insecticide, Repellent | G31: 43192
A32: Y | B32: N/A | C32: Bioworks, Inc. D/B/A Bioworks | D32: 264-1155-AA-68539 | E32: QST 713 strain of dried Bacillus subtilis | F32: Fungicide | G32: 42760
A33: Y | B33: N/A | C33: Imerys Filtration Minerals, Inc. | D33: 73729-1-AA | E33: Diatomaceous earth | F33: Molluscicide, Insecticide | G33: 44292
A34: Y | B34: N/A | C34: Growth Technology Ltd. | D34: 79664-1-AA | E34: IBA (indole-3-butyric acid) | F34: Growth Regulator | G34: 42837
A35: Y | B35: This product can only be applied in greenhouses. | C35: Agro Logistic Systems, Inc. | D35: 70310-7-AA | E35: Margosa oil, azadirachtin | F35: Fungicide, Miticide, Insecticide, Nematicide, Repellent, Growth Regulator | G35: 44357
A36: Y | B36: This product can only be applied in greenhouses. | C36: McLaughlin Gormley King Company, D/B/A MGK | D36: 1021-2876-AA | E36: Margosa oil, azadirachtin | F36: Fungicide, Miticide, Insecticide, Repellent, Nematicide | G36: 44197
... A54: Y | B54: N/A | C54: Verdesian Life Sciences, U.S., LLC, D/B/A/ Verdesian Life Sciences | D54: 73771-5-AA | E54: Potassium phosphite | F54: Fungicide | G54: 44062
A55: Y | C55: Safer, Inc. A Wholly Owned Subsidiary of Woodstream Corporation | D55: 42697-37-ZE | E55: Sulfur | F55: Fungicide, Antimicrobial | G55: 42950
A56: Y | B56: This product can only be applied in greenhouses and nurseries. | C56: Hawthorne Hydroponics LLC D/B/A General Hydroponics | D56: 91865-3-AA | E56: Bacillus velezensis strain: D747 | F56: Bactericide, Fungicide, Antimicrobial | G56: 44083
A57: Y | B57: N/A | C57: Valent Biosciences LLC | D57: 73049-56-ZB | E57: Bacillus thuringiensis subsp. israelensis strain: AM 65-52 | F57: Insecticide | G57: 44097
A58: Y | C58: Vallent Biosciences, LLC | D58: 73049-56-ZB | E58: Bacillus thuringiensis subsp. strain: AM 65-52 | F58: Fungicide | G58: 40757
A59: Y | B59: N/A | C59: Pro Farm Group, Inc. | D59: 84059-27-ZA | E59: Chromobacterium subtsugae strain: PRAA 4-1 | F59: Miticide, Insecticide | G59: 44077
A60: Y | B60: This product is an adjuvant. It can be used with other registered products that meet the legal criteria for use on cannabis, but not independently. | C60: Grow More, Inc. | D60: 70908-50001-AA | E60: Polyethoxylated nonylphenol | F60: Adjuvant | G60: 44062
A61: Y | B61: This product can only be applied around the crop but not to it. | C61: P.F. Harris Manufacturing Company, LLC | D61: 85208-1-AA-3 | E61: Acetic acid | F61: Herbicide | G61: 44062
A62: Y | B62: N/A | C62: Certis USA, LLC | D62: 67702-54-AA-70051 | E62: Caprylic acid, capric acid | F62: Herbicide, Desiccant, Algaecide | G62: 45427
A63: Y | B63: N/A | C63: Maia Products Inc./Ag Division | D63: 8281-2-ZA | E63: IBA (indole-3-butyric acid) | F63: Growth Regulator | G63: 43699
...

Sheet Colorado Allowables
A1: Colorado product name | B1: Company name | C1: EPA Number | D1: Commercial | E1: Home | F1: Hemp | G1: Public Comments | H1: Type | I1: Ingredient1_name | J1: Percent1 | K1: Ingredient2_name | L1: Percent2 | M1: Ingredient3_name | N1: Percent3 | O1: Ingredient4_name | P1: Percent4 | Q1: Ingredient5_name | R1: Percent5 | S1: Ingredient6_name | T1: Percent6 | U1: Ingredient7_name | V1: Percent7
A2: 70% Neem Oil (Monterey) | B2: Lawn and Garden Products, Inc | C2: 70051-2-54705 | D2: No | E2: Yes | F2: No | H2: Fungicide, Insecticide | I2: Clarified Hydrophobic Extract of Neem Oil | J2: 70.000%
A3: AGP4 | B3: AGP4 Advanced Growth & Protection 4 Formula | C3: 0-0-0 | D3: Yes | E3: Yes | F3: Yes | H3: Fungicide, Insecticide | I3: Soybean Oil | J3: 10.000% | K3: Corn Oil | L3: 5.000%
A4: Agree WG | B4: Certis USA, LLC | C4: 70051-47 | D4: Yes | E4: Yes | F4: Yes | G4: Hemp added to label 9-2021 | H4: Insecticide | I4: Bacillus thuringiensis SSP. Aizawai | J4: 50.000%
A5: Agro Pest | B5: Agro Research International LLC | C5: 25(b) | D5: Yes | E5: Yes | F5: Yes | H5: Insecticide | I5: Thyme oil | J5: 13.000% | K5: Rosemary Oil | L5: 10.000%
A6: All Phase | B6: Circadian Crop Sciences LLC | C6: 25(b) | D6: Yes | E6: Yes | F6: Yes | H6: fungicide, bactericide | I6: Potassium Sorbate | J6: 34.700% | K6: Sodium Lauryl Sulfate | L6: 2.000%
A7: AlliCURB MAX | B7: Kemin Industries, Inc. | C7: 0-0-0 | D7: Yes | E7: No | F7: Yes | G7: Commerical Use Only | H7: Insecticide | I7: Castor Oil | J7: 27.000% | K7: Garlic Oil | L7: 8.000%
A8: Almighty | B8: Gropro | C8: 25(b) | D8: Yes | E8: Yes | F8: Yes | H8: nematicide | I8: Geraniol | J8: 4.500%
A9: Ancora | B9: OHP, Inc. | C9: 70051-19-59807 | D9: Yes | E9: Yes | F9: Yes | G9: Hemp on label | H9: Insecticide, Fungicide | I9: Isaria fumosorosea | J9: 20.000%
A10: Athena IPM | B10: Athena Ag, Inc. | C10: 0-0-0 | D10: Yes | E10: Yes | F10: Yes | G10: NEW FORMULA! Check the label! This is the only Athena IPM permitted on cannabis. | H10: Insecticide | I10: Peppermint Oil | J10: 0.250% | K10: Cinnamon Oil | L10: 0.250% | M10: Citric Acid | N10: 0.220%
A11: Atrevia 3.0% SL | B11: Atticus, LLC | C11: 91234-305 | D11: Yes | E11: Yes | F11: Yes | H11: Insecticide | I11: Azadirachtin | J11: 3.000%
A12: Axxe Broad Spectrum Herbicide | B12: BioSafe Systems, LLC | C12: 70299-23 | D12: Yes | E12: Yes | F12: Yes | G12: Greenhouse Use Only. | H12: Herbicide | I12: Ammonium Nonanoate | J12: 40.000%
A13: Aza-Direct Biological Insecticide | B13: Gowan Company | C13: 71908-1-10163 | D13: Yes | E13: Yes | F13: Yes | H13: Insecticide | I13: Azadirachtin | J13: 1.200%
A14: AzaGuard | B14: BioSafe Systems, LLC | C14: 70299-17 | D14: Yes | E14: Yes | F14: Yes | H14: Insecticide | I14: Azadirachtin | J14: 3.000%
A15: AzaMax | B15: Parry America | C15: 71908-1-81268 | D15: Yes | E15: Yes | F15: Yes | G15: hemp added to label 5-2020 | H15: Insecticide, Nematicide | I15: Azadirachtin | J15: 1.200%
A16: AzaSol | B16: Arborjet, Inc. | C16: 81899-4-74578 | D16: Yes | E16: Yes | F16: Yes | H16: Insecticide | I16: Azadirachtin | J16: 6.000%
A17: Azasol WSP | B17: Arborjet Inc. | C17: 81899-4-74578 | D17: Yes | E17: Yes | F17: Yes | H17: Insecticide | I17: Azadirachtin | J17: 6.000%
A18: Azatin O Biological Insecticide | B18: OHP, Inc. | C18: 70051-9-59807 | D18: Yes | E18: Yes | F18: Yes | H18: IGR | I18: Azadirachtin | J18: 4.500%
A19: Azera Gardening | B19: Mclaughlin Gormley King dba MGK | C19: 1021-1872 | D19: No | E19: Yes | F19: No | H19: Insecticide | I19: Azadirachtin | J19: 1.200% | K19: Pyrethrins | L19: 1.400%
A20: Azera Insecticide | B20: McLaughlin Gormley King Company dba MGK | C20: 1021-1872 | D20: Yes | E20: Yes | F20: Yes | H20: Insecticide, Miticide, Fungicide | I20: Azadirachtin | J20: 1.200% | K20: Pyrethrins | L20: 1.400%
A21: Azera Pro | B21: McLaughlin Gormley King Company dba MGK | C21: 1021-1872 | D21: Yes | E21: Yes | F21: Yes | G21: Greenhouse use only | H21: Insecticide | I21: Pyrethrins | J21: 1.400% | K21: Azadirachtin | L21: 1.200%
A22: Bacilirid Biological Fungicide | B22: Koppert Biological Systems, Inc. | C22: 71840-8-89635 | D22: Yes | E22: Yes | F22: Yes | H22: Fungicide | I22: Bacillus subtilis MBI 600 | J22: 11.000%
A23: BellaTrove Companion Maxx WP | B23: DPH Biologicals LLC | C23: 94485-5 | D23: Yes | E23: Yes | F23: Yes | H23: fungicide, bactericide | I23: Bacillus amyloliquefaciens strain ENV503 | J23: 0.149%
A24: Beloukha Garden Herbicide | B24: Certis Belchim B.V. | C24: 91746-8 | D24: Yes | E24: Yes | F24: Yes | H24: Herbicide | I24: Pelargonic Acid | J24: 51.980%
A25: BioCeres EC | B25: Anatis Bioprotection Inc. | C25: 89600-4 | D25: Yes | E25: No | F25: Yes | G25: Hemp on Label | H25: Insecticide | I25: Beauveria bassiana strain ANT-03 | J25: 10.000%
A26: Bioceres GR | B26: Anatis Bioprotection Inc. | C26: 89600-7 | D26: Yes | E26: Yes | F26: Yes | G26: Hemp on label | H26: Insecticide | I26: Beauveria bassiana strain ANT-03 | J26: 7.000%
A27: BioCeres WP | B27: Anatis Bioprotection Inc | C27: 89600-2 | D27: Yes | E27: Yes | F27: Yes | G27: Hemp added to label 5-28-2020. | H27: Insecticide | I27: Beauveria bassiana strain ANT-03 | J27: 20.000%
A28: BioSafe Weed & Grass Killer | B28: BioSafe Systems LLC | C28: 70299-25 | D28: Yes | E28: Yes | F28: Yes | G28: Contact herbicide, will damage all treated leaves | H28: herbicide | I28: Ammonium Nonanoate | J28: 40.000%
A29: BluOX 34 | B29: Clean Chemistry | C29: 92013-5 | D29: Yes | E29: Yes | F29: Yes | H29: Fungicide | I29: Hydrogen Peroxide | J29: 34.500%
A30: BotaniGard 22WP | B30: Certis USA, LLC | C30: 82074-2 | D30: Yes | E30: Yes | F30: Yes | G30: Hemp added to label september 2020 | H30: Insecticide | I30: Beauveria bassiana Strain GHA | J30: 22.000%
A31: BotaniGard ES | B31: Certis USA, LLC | C31: 82074-1 | D31: Yes | E31: Yes | F31: Yes | G31: Hemp added to label September, 2020. | H31: insecticide | I31: Beauveria bassiana Strain GHA | J31: 11.300%
A32: Botanigard Maxx | B32: Certis USA, LLC | C32: 82074-5 | D32: Yes | E32: Yes | F32: Yes | H32: Insecticide | I32: Pyrethrins | J32: 0.750% | K32: Beauveria bassiana Strain GHA | L32: 0.060%
A33: BotaniGard Optima ES | B33: Certis USA, LLC | C33: 82074-17 | D33: Yes | E33: Yes | F33: Yes | H33: Insecticide | I33: Beauveria bassiana Strain GHA | J33: 2.000%
A34: BoteGHA ES | B34: Certis USA, LLC | C34: 82074-1 | D34: Yes | E34: Yes | F34: Yes | G34: Hemp on label | H34: Insecticide | I34: Beauveria bassiana Strain GHA | J34: 11.300%
A35: BoteGHA Optima ES | B35: Certis USA, LLC | C35: 82074-17 | D35: Yes | E35: Yes | F35: Yes | H35: Insecticide | I35: Beauveria bassiana Strain GHA | J35: 2.000%
A36: BotryStop WP | B36: BioWorks, Inc. | C36: 68539-17 | D36: Yes | E36: Yes | F36: Yes | G36: Hemp on label | H36: Fungicide | I36: Ulocladium oudemansii | J36: 45.000%
A37: Brandt Ecotec Plus | B37: Brandt Consolidated, Inc. | C37: 25(b) | D37: Yes | E37: Yes | F37: Yes | H37: Insecticide, Miticide | I37: Rosemary Oil | J37: 10.000% | K37: Geraniol | L37: 5.000% | M37: Peppermint Oil | N37: 2.000%
A38: BRANDT GroFusion | B38: BRANDT Consolidated, Inc. | C38: 57538-74-48813 | D38: Yes | E38: Yes | F38: Yes | H38: Plant Growth Regulator | I38: Cytokinin (Kinetin) | J38: 0.040%
A39: BRANDT OptiThrive | B39: BRANDT Consolidated, Inc. | C39: 90866-23-48813 | D39: Yes | E39: Yes | F39: Yes | H39: Plant Growth Regulator | I39: Cytokinin (Kinetin) | J39: 0.120% | K39: Gamma Aminobutyric Acid (GABA) | L39: 1.000% | M39: Choline Chloride | N39: 2.000%
A40: Brandt Turfzilla | B40: Brandt Consolidated, Inc. | C40: 83416-1-48813 | D40: Yes | E40: Yes | F40: Yes | G40: only for hydroponics, seed treatment, and greenhouse & nursery bedding plants. | H40: fungicide | I40: Phosphorous Acid, Mono- and Di-Potassium Salts of | J40: 45.800%
...

Sheet MSO
A1: Brand | B1: Associated Brand
A2: Curaleaf | B2: Curaleaf
A3: Green Thumb, Inc (GTI)
A4: Trulieve | B4: Trulieve
A5: Verano | B5: Verano
A6: Cresco | B6: Cresco
A7: Curaleaf | B7: Select
A8: Green Thumb, Inc (GTI) | B8: Rise
A9: Trulieve | B9: Zen Leaf
A10: Verano | B10: Verano
A11: Cresco | B11: Sunnyside
A12: Curaleaf | B12: Select
A13: Green Thumb, Inc (GTI) | B13: RYTHM
A14: Green Thumb, Inc (GTI) | B14: Dogwalkers
A15: Green Thumb, Inc (GTI) | B15: Incredibles
... A60: Wana | B60: Wana

Sheet Heavy Metals
A1: Reason | B1: Heavy Metal
A2: Adulterated: Heavy Metal Contamination (Arsenic) | B2: Arsenic
A3: Arsenic | B3: Arsenic
A4: Cadmium | B4: Cadmium
A5: Cadmium | B5: Cadmium
A6: Cadmium, Arsenic | B6: Cadmium
A7: Cadmium, Arsenic | B7: Arsenic
A8: elemental impurities. | B8: Unspecified Heavy Metals
A9: Lead | B9: Lead
A10: Lead Contamination | B10: Lead
A11: Mercury | B11: Mercury
A12: Mercury | B12: Mercury
... A25: Yeast and Mold, Microbials, Arsenic | B25: Arsenic

Sheet ID To Products
A1: Date | B1: State | C1: Doc Link | D1: Type | E1: ID | F1: Company / Producer | G1: Cultivator | I1: Product | J1: Notes
A2: 43675 | B2: Ohio | C2: https://medicalmarijuana.ohio.gov/documents/recalls/recall%20notices%20and%20summaries/archived%20recall%20notices/archived%20recall%20notices.pdf | D2: Voluntary | E2: 43675OhioStandard Wellness | F2: Standard Wellness | H2: M00000021820
H3: M00000028304
A7: 43788 | B7: Ohio | C7: https://medicalmarijuana.ohio.gov/Documents/PatientsCaregivers/One%20Orijin%20Rosin%20Product.pdf | D7: Mandatory | E7: 43788OhioOne Orijin | F7: One Orijin
A8: 43819 | B8: Ohio | C8: https://medicalmarijuana.ohio.gov/documents/recalls/recall%20notices%20and%20summaries/archived%20recall%20notices/archived%20recall%20notices.pdf | D8: Mandatory | E8: 43819OhioGalenas | F8: Galenas | G8: Galenas | H8: M00000034992 | I8: Purple Bomb
G9: Galenas | H9: M00000034991: | I9: Purple Bomb
G10: Galenas | H10: M00000034992 | I10: Purple Bomb
G11: Galenas | H11: M00000034991 | I11: Purple Bomb
G12: Galenas | H12: M00000034985 | I12: THE Organic Strawberry University
A16: 43537 | B16: Ohio | C16: https://medicalmarijuana.ohio.gov/documents/recalls/recall%20notices%20and%20summaries/archived%20recall%20notices/archived%20recall%20notices.pdf | D16: Mandatory | E16: 43537OhioPure Ohio Wellness | F16: Pure Ohio Wellness
A17: 43540 | B17: Ohio | C17: https://medicalmarijuana.ohio.gov/documents/recalls/recall%20notices%20and%20summaries/archived%20recall%20notices/archived%20recall%20notices.pdf | D17: Mandatory | E17: 43540OhioGTI Ohio | F17: GTI Ohio
A18: 44420 | B18: Ohio | C18: https://medicalmarijuana.ohio.gov/documents/recalls/recall%20notices%20and%20summaries/archived%20recall%20notices/archived%20recall%20notices.pdf | D18: Mandatory | E18: 44420OhioBeneleaves Limited | F18: Beneleaves Limited
A19: 44106 | B19: Ohio | C19: https://medicalmarijuana.ohio.gov/documents/recalls/recall%20notices%20and%20summaries/archived%20recall%20notices/archived%20recall%20notices.pdf | D19: Mandatory | E19: 44106OhioVerano Brands | F19: Verano Brands
A20: 44105 | B20: Ohio | C20: https://medicalmarijuana.ohio.gov/documents/recalls/recall%20notices%20and%20summaries/archived%20recall%20notices/archived%20recall%20notices.pdf | D20: Mandatory | E20: 44105OhioVerano Brands | F20: Verano Brands
A21: 44482 | B21: Ohio | C21: https://medicalmarijuana.ohio.gov/documents/recalls/recall%20notices%20and%20summaries/archived%20recall%20notices/archived%20recall%20notices.pdf | D21: Mandatory | E21: 44482OhioCertified Cultivators | F21: Certified Cultivators
A22: 44536 | B22: Ohio | C22: https://medicalmarijuana.ohio.gov/documents/recalls/recall%20notices%20and%20summaries/archived%20recall%20notices/archived%20recall%20notices.pdf | D22: Mandatory | E22: 44536OhioGalenas | F22: Galenas
A23: 44536 | B23: Ohio | C23: https://medicalmarijuana.ohio.gov/documents/recalls/recall%20notices%20and%20summaries/archived%20recall%20notices/archived%20recall%20notices.pdf | D23: Voluntary | E23: 44536OhioGreen Investment Partners, LLC | F23: Green Investment Partners, LLC
A24: 42140 | B24: Maine | C24: https://www.centralmaine.com/2015/09/05/wellness-connection-of-maine-recalls-two-strains-of-medical-marijuana/ | D24: Voluntary | E24: 42140MaineWellness Connection of Maine | F24: Wellness Connection of Maine
A25: 42417 | B25: Colorado | C25: https://sbg.colorado.gov/sites/sbg/files/MED%20Levity%20Advisory%2002192016_1_1.pdf | D25: Mandatory | E25: 42417ColoradoHigh Mountain Medz LLC | F25: High Mountain Medz LLC | H25: Off-Label Pesticides, Myclobutanil and Imidacloprid,
A26: 42417 | B26: Colorado | C26: https://sbg.colorado.gov/sites/sbg/files/MED%20Dr.%20Releaf%20Advisory%2002192016_1_1.pdf | D26: Mandatory | E26: 42417ColoradoDr Releaf Inc | F26: Dr Releaf Inc
A27: 42423 | B27: Colorado | C27: https://sbg.colorado.gov/sites/sbg/files/2.23.16%20XG%20Platinum%20HSA_1_1.pdf | D27: Mandatory | E27: 42423ColoradoXG Platinum Corporation | F27: XG Platinum Corporation
A28: 42424 | B28: Colorado | C28: https://sbg.colorado.gov/sites/sbg/files/Health%20%26%20Safety%20Advisory%20-%20RMO%202-24-16%20Final_1_1.pdf | D28: Mandatory | E28: 42424ColoradoRocky Mountain Organic Medicine Inc | F28: Rocky Mountain Organic Medicine Inc
A29: 42425 | B29: Colorado | C29: https://sbg.colorado.gov/sites/sbg/files/2.25.16%20BTTG%20final_1_1.pdf | D29: Mandatory | E29: 42425ColoradoBack to the Garden Health & Wellness Center LLC | F29: Back to the Garden Health & Wellness Center LLC
A30: 42436 | B30: Colorado | C30: https://sbg.colorado.gov/sites/sbg/files/160307%20Advisory%20-%20Sunrise%20Solutions_Final%20%281%29_2_1.pdf | D30: Mandatory | E30: 42436ColoradoSunrise Solutions LLC | F30: Sunrise Solutions LLC
A31: 42438 | B31: Colorado | C31: https://sbg.colorado.gov/sites/sbg/files/CNW%20Final%2003092016_1.pdf | D31: Mandatory | E31: 42438ColoradoArtisanal Medicinals. | F31: Artisanal Medicinals.
A32: 42439 | B32: Colorado | C32: https://sbg.colorado.gov/sites/sbg/files/Headquarters%20Emp%20HSA%20final%2003102016_1_1.pdf | D32: Mandatory | E32: 42439ColoradoHeadquarters Emporium and Dispensary LLC | F32: Headquarters Emporium and Dispensary LLC
A33: 42439 | B33: Colorado | C33: https://sbg.colorado.gov/sites/sbg/files/SkinnyPineapple%20Final%2003102016_1_1.pdf | D33: Mandatory | E33: 42439ColoradoSkinny Pineapple Inc | F33: Skinny Pineapple Inc
A34: 42443 | B34: Colorado | C34: https://sbg.colorado.gov/sites/sbg/files/AMA%20Final%2003142016_1_1.pdf | D34: Mandatory | E34: 42443ColoradoAdvanced Medical Alternatives LLC | F34: Advanced Medical Alternatives LLC
A35: 42443 | B35: Colorado | C35: https://sbg.colorado.gov/sites/sbg/files/RR%20Services%20Final%2003142016_1_1.pdf | D35: Mandatory | E35: 42443ColoradoRR Services LLC | F35: RR Services LLC
A36: 42446 | B36: Colorado | C36: https://sbg.colorado.gov/sites/sbg/files/MGI%20HSA%2003172016_1_1.pdf | D36: Mandatory | E36: 42446ColoradoMGI Inc | F36: MGI Inc
A37: 42450 | B37: Colorado | C37: https://sbg.colorado.gov/sites/sbg/files/Colorados%20Best%2003212016_1.pdf | D37: Mandatory | E37: 42450ColoradoColorados Best Inc | F37: Colorados Best Inc
... A225: 45140 | B225: Washington | C225: https://lcb.wa.gov/marj/notice_of_recalls | D225: Mandatory | E225: 45140WashingtonOlympic Reef, LLC | F225: Olympic Reef, LLC

Sheet Batches
A1: Research ID | B1: Batch ID | C1: Medical Marijuana Center | D1: Medical Marijuana Cultivation License | E1: MM Manufacturer's | F1: Manufacturer's License | G1: Retail Marijuana Cultivation License | H1: Retail Store | I1: Retail Products Manufacturing
A2: CO424171 | B2: 2015-03-21-Drying Room-H | C2: 402-00242 | D2: 403-00365
A3: CO424171 | B3: 2015-05-08-Drying Room-H | C3: 402-00242 | D3: 403-00365
A4: CO424171 | B4: 2016-01-11-Drying Room-H | C4: 402-00242 | D4: 403-00365
A5: CO424171 | B5: 707-082615-8 | C5: 402-00242 | D5: 403-00365
A6: CO424171 | B6: 707HB-062815-5 | C6: 402-00242 | D6: 403-00365
A7: CO424171 | B7: 707HB-071315-10 | C7: 402-00242 | D7: 403-00365
A8: CO424171 | B8: 707HB-071315-10 | C8: 402-00242 | D8: 403-00365
A9: CO424171 | B9: 707HB-102315-6 | C9: 402-00242 | D9: 403-00365
A10: CO424171 | B10: 707HB-111815-1 | C10: 402-00242 | D10: 403-00365
A11: CO424171 | B11: 707HB-112915-1 | C11: 402-00242 | D11: 403-00365
A12: CO424171 | B12: 707HB-120815-1 | C12: 402-00242 | D12: 403-00365
A13: CO424171 | B13: AK48-071115-2 | C13: 402-00242 | D13: 403-00365
... A274: CO424171 | B274: Tangilope-100515-10 | C274: 402-00242 | D274: 403-00365
A275: CO424172 | B275: 012016 tanq1 | D275: 403-01366 | F275: 404-00352
A276: CO424172 | B276: 012016 tranq1 | D276: 403-01366 | F276: 404-00352
A277: CO424172 | B277: 012016 Tranq2 | D277: 403-01366 | F277: 404-00352
A278: CO424172 | B278: 1/25/16 Purple Dream (PD012516) | D278: 403-01366 | F278: 404-00352
A279: CO424172 | B279: 1/25/16 Ruskin Chronic (RC012516) | D279: 403-01366 | F279: 404-00352
A280: CO424172 | B280: 1/25/16 Shoreline #4 (S4012516) | D280: 403-01366 | F280: 404-00352
A281: CO424172 | B281: 1/25/16 Special Sour Diesel (SS012516) | D281: 403-01366 | F281: 404-00352
A282: CO424172 | B282: 1/25/16 Sugar Black Rose (SB012516) | D282: 403-01366 | F282: 404-00352
A283: CO424172 | B283: 1/26/16 Sugar Black Rose (SB012616) | D283: 403-01366 | F283: 404-00352
A284: CO424172 | B284: 1/26/2016 Shoreline #1 (S1012616) | D284: 403-01366 | F284: 404-00352
A285: CO424172 | B285: 1/28/16 Chem Dawg (CD012516) | D285: 403-01366 | F285: 404-00352
A286: CO424172 | B286: 1-26-15 Shoreline #3 (SH012615) | D286: 403-01366 | F286: 404-00352
... A319: CO424172 | B319: 8-5-15 Shoreline | D319: 403-01366 | F319: 404-00352
A320: CO424172 | B320: 1-29-16 Buddha's Sister (BS012916) | C320: 402-00875 | D320: 403-01367, 403-01571
A321: CO424172 | B321: 1-29-16 Chem Dawg (CD012916) | C321: 402-00875 | D321: 403-01367, 403-01571
A322: CO424172 | B322: 1/4/16 Grape Ape | C322: 402-00875 | D322: 403-01367, 403-01571
A323: CO424172 | B323: 1/4/16 NYCD Blast | C323: 402-00875 | D323: 403-01367, 403-01571
A324: CO424172 | B324: 10-28-15 OJ Blast | C324: 402-00875 | D324: 403-01367, 403-01571
A325: CO424172 | B325: 1-12-16 Grape Ape(R) | C325: 402-00875 | D325: 403-01367, 403-01571
A326: CO424172 | B326: 1-13-16 OJ | C326: 402-00875 | D326: 403-01367, 403-01571
A327: CO424172 | B327: 1-19-16 Shoreline #3 | C327: 402-00875 | D327: 403-01367, 403-01571
A328: CO424172 | B328: 12-22-15 AK-47 | C328: 402-00875 | D328: 403-01367, 403-01571
A329: CO424172 | B329: 12-22-15 Lost Coast OG | C329: 402-00875 | D329: 403-01367, 403-01571
A330: CO424172 | B330: 12-22-15 NYCD | C330: 402-00875 | D330: 403-01367, 403-01571
A331: CO424172 | B331: 12-23 & 24-15 AK-47 | C331: 402-00875 | D331: 403-01367, 403-01571
... A419: CO424172 | B419: Chiesel (TQAD) | C419: 402-01078 | D419: 403-01676
...
